Workbook
Name Time: 'B5'!$D$22

Sheet Profit & Loss
B2: Text for B/S P&L item | C2: 44562 | D2: 44593 | E2: 44621 | F2: 44652 | G2: 44682 | H2: 44713 | I2: 44743 | J2: 44774 | K2: 44805 | L2: 44835 | M2: 44866 | N2: 44896 | O2: YTD 2023 | P2: 44927 | Q2: 44958 | R2: 44986 | S2: 45017 | T2: 45047 | U2: 45078 | V2: 45108 | W2: 45139 | X2: 45170 | Y2: 45200 | Z2: 45231 | AA2: 45266 | AB2: YTD 2023 | AC2: 45292 | AD2: 45323 | AE2: 45352 | AF2: 45383 | AG2: 45413 | AH2: 45444 | AI2: 45474 | AJ2: 45505 | AK2: 45536 | AL2: 45566 | AM2: 45597 | AN2: 45632 | AO2: YTD 2024 | AP2: 45658 | AQ2: 45689 | AR2: 45717 | AS2: 45748 | AT2: 45778 | AU2: 45809 | AV2: 45839 | AW2: 45870 | AX2: 45901 | AY2: 45931 | AZ2: 45962 | BA2: 45997 | BB2: YTD 2025 | BC2: 46023 | BD2: 46054 | BE2: 46082 | BF2: 46113 | BG2: 46143 | BH2: 46174 | BI2: 46204 | BJ2: 46235 | BK2: 46266 | BL2: 46296 | BM2: 46327 | BN2: 46362 | BO2: YTD 2026
B3: Profit and loss statement | C3: 0
B4: 4010000000 Sales PP Unit | C4: -58033.76 | D4: 0 | E4: 0 | F4: 0 | G4: 0 | H4: 0 | I4: 0 | J4: -1217492.9 | K4: -1849798.6 | L4: -136363.64 | M4: -221153.84 | N4: 0 | O4: =SUBTOTAL(9,C4:N4) -> -3482842.7 | P4: -1198350.1 | Q4: -1198350.1 | R4: 0 | S4: -136486.49 | T4: -86094.19 | U4: 0 | V4: -117821.58 | W4: -1054772.7 | X4: -66754.87 | Y4: -2100761.9 | Z4: -1248566 | AA4: -1853156.9 | AB4: =SUM(P4:AA4) -> -9061114.9 | AC4: 0 | AD4: 0 | AE4: 0 | AF4: 0 | AG4: 0 | AH4: 0 | AI4: -141158.54 | AJ4: -51648.26 | AK4: 0 | AL4: -84326.76 | AM4: -1110193 | AN4: -2612066 | AO4: =SUM(AC4:AN4) -> -3999392.6 | AP4: 0 | AQ4: -332868.91 | AR4: =VLOOKUP(B4,'[1]Sheet1 (2)'!$B$2:$C$397,2,0) -> 0 | AS4: =VLOOKUP(B4,'[2]Sheet1 (2)'!$B$2:$C$404,2,0) -> 0 | AT4: -183257.62 | AU4: -50235.39 | AV4: 0 | AW4: 0 | AX4: 0 | AY4: 0 | AZ4: -151542.78 | BA4: -42078.01 | BB4: =SUM(AP4:BA4) -> -759982.71 | BC4: 0 | BD4: 0 | BE4: 0 | BF4: -115467.26 | BG4: 0 | BH4: 0 | BI4: 0 | BO4: =SUM(BC4:BN4) -> -115467.26
B5: 4010001000 Sales PP Discount | C5: 3837.96 | D5: 0 | E5: 0 | F5: 0 | G5: 0 | H5: 0 | I5: 0 | J5: 0 | K5: 0 | L5: 0 | M5: 0 | N5: 0 | O5: =SUBTOTAL(9,C5:N5) -> 3837.96 | P5: 0 | Q5: 0 | R5: 0 | S5: 0 | T5: 12445.54 | U5: 0 | V5: 3252.04 | W5: 0 | X5: 0 | Y5: 0 | Z5: 0 | AA5: 0 | AB5: =SUM(P5:AA5) -> 15697.58 | AC5: 0 | AD5: 0 | AE5: 0 | AF5: 0 | AG5: 0 | AH5: 0 | AI5: 0 | AJ5: 2898.26 | AK5: 0 | AL5: 0 | AM5: 0 | AN5: 0 | AO5: =SUM(AC5:AN5) -> 2898.26 | AP5: 0 | AQ5: 0 | AR5: 0 | AS5: 0 | AT5: 0 | AU5: 2818.98 | AV5: 0 | AW5: 0 | AX5: 0 | AY5: 0 | AZ5: 4536.79 | BA5: 0 | BB5: =SUM(AP5:BA5) -> 7355.77 | BC5: 0 | BD5: 0 | BE5: 0 | BF5: 0 | BG5: 0 | BH5: 0 | BI5: 0 | BO5: =SUM(BC5:BN5) -> 0
B6: 4010300100 Sales PP Attachment Accessories | J6: -21410.81 | K6: -19858.66 | L6: 0 | M6: 0 | N6: 0 | O6: =SUBTOTAL(9,C6:N6) -> -41269.47 | P6: -21649.88 | Q6: -21649.88 | R6: 0 | S6: 0 | T6: 0 | U6: 0 | V6: 0 | W6: 0 | X6: -9219.15 | Y6: 0 | Z6: 0 | AA6: 0 | AB6: =SUM(P6:AA6) -> -52518.91 | AC6: 0 | AD6: 0 | AE6: 0 | AF6: 0 | AG6: 0 | AH6: 0 | AI6: 0 | AJ6: 0 | AK6: 0 | AL6: -3571.33 | AM6: 0 | AN6: 0 | AO6: =SUM(AC6:AN6) -> -3571.33 | AP6: 0 | AQ6: -14692.07 | AR6: =VLOOKUP(B6,'[1]Sheet1 (2)'!$B$2:$C$397,2,0) -> 0 | AS6: =VLOOKUP(B6,'[2]Sheet1 (2)'!$B$2:$C$404,2,0) -> 0 | AT6: -1456.67 | AU6: 0 | AV6: 0 | AW6: 0 | AX6: 0 | AY6: 0 | AZ6: 0 | BA6: 0 | BB6: =SUM(AP6:BA6) -> -16148.74 | BC6: 0 | BD6: 0 | BE6: 0 | BF6: -2661.4 | BG6: 0 | BH6: 0 | BI6: 0 | BO6: =SUM(BC6:BN6) -> -2661.4
B7: 4010400000 Sales PP Power System Project | K7: -61497.45 | L7: 0 | M7: -77268.68 | N7: 0 | O7: =SUBTOTAL(9,C7:N7) -> -138766.13 | P7: 0 | Q7: 0 | R7: 0 | S7: 0 | T7: 0 | U7: 0 | V7: 0 | W7: 0 | X7: 0 | Y7: -528040 | Z7: 0 | AA7: 0 | AB7: =SUM(P7:AA7) -> -528040 | AC7: 0 | AD7: 0 | AE7: -694532.85 | AF7: 0 | AG7: 0 | AH7: 0 | AI7: 0 | AJ7: 0 | AK7: 0 | AL7: 0 | AM7: 0 | AN7: 0 | AO7: =SUM(AC7:AN7) -> -694532.85 | AP7: 0 | AQ7: 0 | AR7: 0 | AS7: 0 | AT7: 0 | AU7: 0 | AV7: -90391.32 | AW7: 0 | AX7: 0 | AY7: 0 | AZ7: 0 | BA7: 0 | BB7: =SUM(AP7:BA7) -> -90391.32 | BC7: 0 | BD7: 0 | BE7: -494355.44 | BF7: 0 | BG7: 0 | BH7: 0 | BI7: 0 | BO7: =SUM(BC7:BN7) -> -494355.44
B8: 4010401000 Sales PP Power System Accrual/Defferal | S8: 2597.52 | T8: 0 | U8: 0 | V8: 0 | W8: -331221.69 | X8: -132089.61 | Y8: 463311.3 | Z8: 0 | AA8: -565357.01 | AB8: =SUM(P8:AA8) -> -562759.49 | AC8: -17875.68 | AD8: -3003.32 | AE8: 586236.01 | AF8: 0 | AG8: 0 | AH8: 0 | AI8: 0 | AJ8: 0 | AK8: 0 | AL8: 0 | AM8: 0 | AN8: 0 | AO8: =SUM(AC8:AN8) -> 565357.01 | AP8: 0 | AQ8: 0 | AR8: 0 | AS8: 0 | AT8: 0 | AU8: 0 | AV8: 0 | AW8: 0 | AX8: 0 | AY8: 0 | AZ8: 0 | BA8: -435432.41 | BB8: =SUM(AP8:BA8) -> -435432.41 | BC8: -180.87 | BD8: -921.2 | BE8: 436534.48 | BF8: 0 | BG8: 0 | BH8: 0 | BI8: 0 | BO8: =SUM(BC8:BN8) -> 435432.41
B9: 4010402000 Sales PP Power System Acc Defferal | K9: 61497.45 | L9: 0 | M9: 77268.68 | N9: 0 | O9: =SUBTOTAL(9,C9:N9) -> 138766.13 | P9: -9.94 | Q9: -178.41 | R9: -230.87 | S9: 0 | T9: 0 | U9: 0 | V9: 0 | W9: -61497.45 | X9: 0 | Y9: 59878.98 | Z9: -1245.5 | AA9: -84409.3 | AB9: =SUM(P9:AA9) -> -87692.49 | AC9: -577.03 | AD9: -340.37 | AE9: 78698.37 | AF9: -4187.48 | AG9: -1673.57 | AH9: -103.61 | AI9: -1796.73 | AJ9: -18492.13 | AK9: -78.04 | AL9: -2131.98 | AM9: -1252.87 | AN9: -13888.03 | AO9: =SUM(AC9:AN9) -> 34176.53 | AP9: 0 | AQ9: -4207.88 | AR9: =VLOOKUP(B9,'[1]Sheet1 (2)'!$B$2:$C$397,2,0) -> -1534.87 | AS9: =VLOOKUP(B9,'[2]Sheet1 (2)'!$B$2:$C$404,2,0) -> -2172.28 | AT9: -2093.48 | AU9: -4424.91 | AV9: 88991.82 | AW9: 0 | AX9: -2599.3 | AY9: -2933.71 | AZ9: -45.69 | BA9: -90391.32 | BB9: =SUM(AP9:BA9) -> -21411.62 | BC9: 0 | BD9: -6304.41 | BE9: 45974.93 | BF9: -889.35 | BG9: 0 | BH9: -114.76 | BI9: -115.56 | BO9: =SUM(BC9:BN9) -> 38550.85
B10: 4010600000 Sales PP Attachment | AC10: 0 | AD10: 0 | AE10: 0 | AF10: 0 | AG10: 0 | AH10: 0 | AI10: 0 | AJ10: 0 | AK10: -39407.89 | AL10: 0 | AM10: 0 | AN10: 0 | AO10: =SUM(AC10:AN10) -> -39407.89 | AP10: 0 | AQ10: 0 | AR10: 0 | AS10: 0 | AT10: 0 | AU10: 0 | AV10: 0 | AW10: 0 | AX10: 0 | AY10: 0 | AZ10: 0 | BA10: 0 | BB10: =SUM(AP10:BA10) -> 0 | BC10: 0 | BD10: 0 | BE10: 0 | BF10: 0 | BG10: 0 | BH10: 0 | BI10: 0 | BO10: =SUM(BC10:BN10) -> 0
B11: 4011500000 IFRS 15 Prime Product | K11: -986368.35 | L11: 0 | M11: 0 | N11: 0 | O11: =SUBTOTAL(9,C11:N11) -> -986368.35 | P11: 0 | Q11: 0 | R11: 0 | S11: 0 | T11: 0 | U11: 0 | V11: 0 | W11: 0 | X11: -599.25 | Y11: -743.07 | Z11: -719.1 | AA11: -743.07 | AB11: =SUM(P11:AA11) -> -2804.49 | AC11: -743.07 | AD11: -695.13 | AE11: -743.07 | AF11: -719.09 | AG11: -743.07 | AH11: -719.09 | AI11: -141616.82 | AJ11: -743.06 | AK11: -119.85 | AL11: 0 | AM11: 0 | AN11: -431698.56 | AO11: =SUM(AC11:AN11) -> -578540.81 | AP11: 0 | AQ11: -331372.52 | AR11: =VLOOKUP(B11,'[1]Sheet1 (2)'!$B$2:$C$397,2,0) -> 0 | AS11: =VLOOKUP(B11,'[2]Sheet1 (2)'!$B$2:$C$404,2,0) -> 0 | AT11: 0 | AU11: 0 | AV11: 0 | AW11: 0 | AX11: 0 | AY11: 0 | AZ11: 0 | BA11: -41467.99 | BB11: =SUM(AP11:BA11) -> -372840.51 | BC11: 0 | BD11: 0 | BE11: 0 | BF11: -114656.9 | BG11: 0 | BH11: 0 | BI11: 0 | BO11: =SUM(BC11:BN11) -> -114656.9
B12: 4011500100 IFRS 15 Prime Product unit Adjustment | K12: 995141.34 | L12: 0 | M12: 0 | N12: 0 | O12: =SUBTOTAL(9,C12:N12) -> 995141.34 | P12: 0 | Q12: 0 | R12: 0 | S12: 0 | T12: 0 | U12: 0 | V12: 0 | W12: 0 | X12: 0 | Y12: 0 | Z12: 0 | AA12: 0 | AB12: =SUM(P12:AA12) -> 0 | AC12: 0 | AD12: 0 | AE12: 0 | AF12: 0 | AG12: 0 | AH12: 0 | AI12: 141158.54 | AJ12: 0 | AK12: 0 | AL12: 0 | AM12: 0 | AN12: 432546.01 | AO12: =SUM(AC12:AN12) -> 573704.55 | AP12: 0 | AQ12: 332868.9 | AR12: =VLOOKUP(B12,'[1]Sheet1 (2)'!$B$2:$C$397,2,0) -> 0 | AS12: =VLOOKUP(B12,'[2]Sheet1 (2)'!$B$2:$C$404,2,0) -> 0 | AT12: 0 | AU12: 0 | AV12: 0 | AW12: 0 | AX12: 0 | AY12: 0 | AZ12: 0 | BA12: 42078 | BB12: =SUM(AP12:BA12) -> 374946.9 | BC12: 0 | BD12: 0 | BE12: 0 | BF12: 115467.25 | BG12: 0 | BH12: 0 | BI12: 0 | BO12: =SUM(BC12:BN12) -> 115467.25
B13: PRIME PRODUCT | C13: =SUM(C4:C12) -> -54195.8 | D13: =SUM(D4:D12) -> 0 | E13: =SUM(E4:E12) -> 0 | F13: =SUM(F4:F12) -> 0 | G13: =SUM(G4:G12) -> 0 | H13: =SUM(H4:H12) -> 0 | I13: =SUM(I4:I12) -> 0 | J13: =SUM(J4:J12) -> -1238903.7 | ... N13: =SUM(N4:N12) -> 0 | O13: =SUM(C13:N13) -> -3511501.2 | P13: =SUM(P4:P12) -> -1220009.9 | Q13: =SUM(Q4:Q12) -> -1220178.4 | R13: =SUM(R4:R12) -> -230.87 | S13: =SUM(S4:S12) -> -133888.97 | T13: =SUM(T4:T12) -> -73648.65 | U13: =SUM(U4:U12) -> 0 | V13: =SUM(V4:V12) -> -114569.54 | W13: =SUM(W4:W12) -> -1447491.9 | ... BO13: =SUM(BO4:BO12) -> -137690.49
B14: 4020100101 Sales Parts Through Counter | C14: -4673022.8 | D14: -4680697.2 | E14: -5357309.4 | F14: -4581013.4 | G14: -5610312.7 | H14: -6382204.7 | I14: -5446430.7 | J14: -3544566.2 | K14: -8781431.1 | L14: -7534841.5 | M14: -9220274.5 | N14: -9671792.2 | O14: =SUBTOTAL(9,C14:N14) -> -75483896 | P14: -6903467.4 | Q14: -4489216.9 | R14: -10302351 | S14: -5795173.8 | T14: -7515693.3 | U14: -5919972.3 | V14: -4809437 | W14: -5348221.4 | X14: -5246466.7 | Y14: -5095288.3 | Z14: -3434892.4 | AA14: -4609744.4 | AB14: =SUM(P14:AA14) -> -69469925 | AC14: -3769518.3 | AD14: -4610219 | AE14: -4865200.8 | AF14: -4198492.5 | AG14: -4920435.6 | AH14: -4315235.3 | AI14: -4831902 | AJ14: -1415125 | AK14: -9517097.1 | AL14: -4666708.2 | AM14: -4005350.7 | AN14: -3626109.2 | AO14: =SUM(AC14:AN14) -> -54741394 | AP14: -3289691.5 | AQ14: -3228428.6 | AR14: =VLOOKUP(B14,'[1]Sheet1 (2)'!$B$2:$C$397,2,0) -> -2208403.6 | AS14: =VLOOKUP(B14,'[2]Sheet1 (2)'!$B$2:$C$404,2,0) -> -2528704.8 | AT14: -3558221.2 | AU14: -3456846.2 | AV14: -2911914.2 | AW14: -2993312.9 | AX14: -2743175.7 | AY14: -3154594.6 | AZ14: -3907670 | BA14: -2873619.1 | BB14: =SUM(AP14:BA14) -> -36854582 | BC14: -2857496.4 | BD14: -3903125.1 | BE14: -3737634.2 | BF14: -3148686.3 | BG14: -2414605 | BH14: -2861914.5 | BI14: -3199594.6 | BO14: =SUM(BC14:BN14) -> -22123056
B15: 4020100202 Sales Parts Through Service Flat Rate | C15: -9457.29 | D15: -11473.07 | E15: 0 | F15: -33227.21 | G15: -65960.17 | H15: -798391.47 | I15: -17949.05 | J15: 0 | K15: 0 | L15: 0 | M15: 0 | N15: -1101488.4 | O15: =SUBTOTAL(9,C15:N15) -> -2037946.7 | P15: 0 | Q15: -571752.83 | R15: -791010.66 | S15: -276689.37 | T15: -748037.33 | U15: -888742.45 | V15: -592512.15 | W15: -617667.03 | X15: -658056.78 | Y15: -783989.16 | Z15: -726585.07 | AA15: -1203804.5 | AB15: =SUM(P15:AA15) -> -7858847.3 | AC15: -409997.09 | AD15: -1520295 | AE15: -760184.13 | AF15: -938457.36 | AG15: -1392552.4 | AH15: -1141536.9 | AI15: -1251075.3 | AJ15: -1101877 | AK15: -1527652.1 | AL15: -1132959.5 | AM15: -1137260.4 | AN15: -1523606.1 | AO15: =SUM(AC15:AN15) -> -13837453 | AP15: -941238.03 | AQ15: -1119248.1 | AR15: =VLOOKUP(B15,'[1]Sheet1 (2)'!$B$2:$C$397,2,0) -> -743599.4 | AS15: =VLOOKUP(B15,'[2]Sheet1 (2)'!$B$2:$C$404,2,0) -> -561730.55 | AT15: -690693.76 | AU15: -248781.28 | AV15: -38895.8 | AW15: -287623.57 | AX15: -659890.02 | AY15: -191804.31 | AZ15: -35922.93 | BA15: -534368.93 | BB15: =SUM(AP15:BA15) -> -6053796.6 | BC15: -320423.9 | BD15: -198045.15 | BE15: -420995.6 | BF15: -258893.01 | BG15: -596968.85 | BH15: -514855.07 | BI15: -290891.26 | BO15: =SUM(BC15:BN15) -> -2601072.8
B16: 4020100206 Sales Parts Through Service Flat Rate Variance | C16: 0.01 | D16: 471.93 | E16: 0 | F16: -0.01 | G16: 23587.1 | H16: 33038.42 | I16: 133.07 | J16: 0 | K16: 0 | L16: 0 | M16: 0 | N16: 46421.01 | O16: =SUBTOTAL(9,C16:N16) -> 103651.53 | P16: 0 | Q16: 35871.76 | R16: 60591.39 | S16: 45319.51 | T16: 15489.23 | U16: 13652.22 | V16: 18775.66 | W16: 33418.68 | X16: 1832.8 | Y16: -18355.27 | Z16: -7959.88 | AA16: -4046.58 | AB16: =SUM(P16:AA16) -> 194589.52 | AC16: 8411.52 | AD16: 29341.59 | AE16: 19588.35 | AF16: 11149.11 | AG16: 33841.64 | AH16: -39894.09 | AI16: -6494.88 | AJ16: 3380.39 | AK16: -22645.63 | AL16: -20370.16 | AM16: -23745.23 | AN16: -4585.62 | AO16: =SUM(AC16:AN16) -> -12023.01 | AP16: 946.4 | AQ16: -28576.87 | AR16: =VLOOKUP(B16,'[1]Sheet1 (2)'!$B$2:$C$397,2,0) -> -6310.54 | AS16: =VLOOKUP(B16,'[2]Sheet1 (2)'!$B$2:$C$404,2,0) -> 60475.36 | AT16: 14437.56 | AU16: 48.85 | AV16: 5369.78 | AW16: -4392.48 | AX16: -903.63 | AY16: -714.44 | AZ16: -613.78 | BA16: 1663.86 | BB16: =SUM(AP16:BA16) -> 41430.07 | BC16: -5876.67 | BD16: -1102.18 | BE16: -903.92 | BF16: 22575.88 | BG16: -12340.37 | BH16: -13127.59 | BI16: 5928.33 | BO16: =SUM(BC16:BN16) -> -4846.52
B17: 4020400101 Sales Parts Through Counter CORE | C17: -49623.57 | D17: -39159.6 | E17: -57552.92 | F17: -318317.4 | G17: -112916.5 | H17: -45099.88 | I17: -28251.79 | J17: -37039.66 | K17: -63609.83 | L17: -36077.2 | M17: -65520.64 | N17: -61358.9 | O17: =SUBTOTAL(9,C17:N17) -> -914527.89 | P17: -119266.71 | Q17: -87590.32 | R17: -66817.8 | S17: -58517.07 | T17: -48568.27 | U17: -61179.96 | V17: -50416.13 | W17: -29133.99 | X17: -24755.82 | Y17: -16331.08 | Z17: -5046.25 | AA17: -3970.72 | AB17: =SUM(P17:AA17) -> -571594.12 | AC17: -11477.09 | AD17: -162.03 | AE17: -4471.36 | AF17: -5976.62 | AG17: -723.7 | AH17: 0 | AI17: -13110.72 | AJ17: -6808.54 | AK17: -1289.54 | AL17: 0 | AM17: -65.17 | AN17: -1053.06 | AO17: =SUM(AC17:AN17) -> -45137.83 | AP17: 0 | AQ17: -1042.11 | AR17: =VLOOKUP(B17,'[1]Sheet1 (2)'!$B$2:$C$397,2,0) -> -1191.1 | AS17: =VLOOKUP(B17,'[2]Sheet1 (2)'!$B$2:$C$404,2,0) -> -1770.54 | AT17: -85425.21 | AU17: -85609.27 | AV17: -189341.33 | AW17: -128227.88 | AX17: -96785.03 | AY17: -176305.86 | AZ17: -200441.27 | BA17: -135232.25 | BB17: =SUM(AP17:BA17) -> -1101371.9 | BC17: -123857.75 | BD17: -150909.48 | BE17: -160529.64 | BF17: -204842.37 | BG17: -102099.91 | BH17: -110298.9 | BI17: -158473.97 | BO17: =SUM(BC17:BN17) -> -1011012
B18: 4020400202 Sales Parts Through Service CORE Flat Rate | P18: 0 | Q18: 0 | R18: 0 | S18: 0 | T18: 0 | U18: 0 | V18: 0 | W18: -2235.37 | X18: 0 | Y18: 0 | Z18: 0 | AA18: 0 | AB18: =SUM(P18:AA18) -> -2235.37 | AC18: 0 | AD18: 0 | AE18: 0 | AF18: 0 | AG18: -17970.59 | AH18: 0 | AI18: 0 | AJ18: -2855.7 | AK18: 0 | AL18: 0 | AM18: 0 | AN18: 0 | AO18: =SUM(AC18:AN18) -> -20826.29 | AP18: 0 | AQ18: 1638.89 | AR18: =VLOOKUP(B18,'[1]Sheet1 (2)'!$B$2:$C$397,2,0) -> 6532.28 | AS18: =VLOOKUP(B18,'[2]Sheet1 (2)'!$B$2:$C$404,2,0) -> 0 | AT18: 0 | AU18: 0 | AV18: 0 | AW18: 0 | AX18: 0 | AY18: 0 | AZ18: 0 | BA18: -3045.22 | BB18: =SUM(AP18:BA18) -> 5125.95 | BC18: 0 | BD18: -1327.38 | BE18: -813.73 | BF18: 0 | BG18: 0 | BH18: 0 | BI18: 0 | BO18: =SUM(BC18:BN18) -> -2141.11
B19: 4020500100 Sales Parts SOS Bottle | C19: -27.12 | D19: -7.59 | E19: -65.33 | F19: -11.75 | G19: -26.78 | H19: -32.69 | I19: -44.99 | J19: -28.09 | K19: -53.36 | L19: -91.36 | M19: -64.11 | N19: -114.99 | O19: =SUBTOTAL(9,C19:N19) -> -568.16 | P19: -47.33 | Q19: -32.64 | R19: -75.89 | S19: 0 | T19: -36.6 | U19: -43.11 | V19: -66.17 | W19: -41.55 | X19: 0 | Y19: -34.21 | Z19: -38.56 | AA19: -3.64 | AB19: =SUM(P19:AA19) -> -419.7 | AC19: -3.64 | AD19: -59.49 | AE19: -4.79 | AF19: -36.33 | AG19: -28.55 | AH19: -1.73 | AI19: -4.8 | AJ19: 0 | AK19: 0 | AL19: -6.26 | AM19: -0.93 | AN19: 0 | AO19: =SUM(AC19:AN19) -> -146.52 | AP19: 0 | AQ19: -22.01 | AR19: =VLOOKUP(B19,'[1]Sheet1 (2)'!$B$2:$C$397,2,0) -> -56.63 | AS19: =VLOOKUP(B19,'[2]Sheet1 (2)'!$B$2:$C$404,2,0) -> -30.18 | AT19: -20.35 | AU19: -12.81 | AV19: -59.29 | AW19: 0 | AX19: -8.29 | AY19: -25.33 | AZ19: -6.55 | BA19: -39.35 | BB19: =SUM(AP19:BA19) -> -280.79 | BC19: -37.62 | BD19: -65.1 | BE19: -2.88 | BF19: -11.08 | BG19: -8.32 | BH19: -6.56 | BI19: -7.57 | BO19: =SUM(BC19:BN19) -> -139.13
B20: 4020500107 Sales Parts SOS Lab Bottle Actual Discount | BC20: 0 | BD20: 0 | BE20: 0.02 | BF20: 0 | BG20: 0.02 | BH20: 0 | BI20: 0 | BO20: =SUM(BC20:BN20) -> 0.04
B21: 4020500101 Sales Parts Through Counter USED Parts | C21: -133950.59 | D21: 0 | E21: -16032.99 | F21: 0 | G21: 0 | H21: -81729.26 | I21: 0 | J21: -60946.7 | K21: -23529.41 | L21: 0 | M21: 0 | N21: 0 | O21: =SUBTOTAL(9,C21:N21) -> -316188.95 | P21: 0 | Q21: 0 | R21: 0 | S21: 0 | T21: 0 | U21: 0 | V21: -43333.33 | W21: 0 | X21: -93567.84 | Y21: -6354.77 | Z21: 0 | AA21: 0 | AB21: =SUM(P21:AA21) -> -143255.94 | AC21: -40134.31 | AD21: 0 | AE21: -39126.74 | AF21: 0 | AG21: 0 | AH21: 0 | AI21: 0 | AJ21: 0 | AK21: 0 | AL21: 0 | AM21: 0 | AN21: 0 | AO21: =SUM(AC21:AN21) -> -79261.05 | AP21: 0 | AQ21: 0 | AR21: 0 | AS21: 0 | AT21: 0 | AU21: 0 | AV21: 0 | AW21: 0 | AX21: 0 | AY21: 0 | AZ21: 0 | BA21: 0 | BB21: =SUM(AP21:BA21) -> 0 | BC21: 0 | BD21: 0 | BE21: 0 | BF21: 0 | BG21: 0 | BH21: 0 | BI21: 0 | BO21: =SUM(BC21:BN21) -> 0
B22: 4020500200 Sales Digital Subscription | AC22: 0 | AD22: 0 | AE22: 0 | AF22: 0 | AG22: 0 | AH22: 0 | AI22: 0 | AJ22: 0 | AK22: 0 | AL22: 0 | AM22: 0 | AN22: -287.43 | AO22: =SUM(AC22:AN22) -> -287.43 | AP22: 0 | AQ22: -197.62 | AR22: =VLOOKUP(B22,'[1]Sheet1 (2)'!$B$2:$C$397,2,0) -> 0 | AS22: =VLOOKUP(B22,'[2]Sheet1 (2)'!$B$2:$C$404,2,0) -> -190.12 | AT22: 0 | AU22: -1580.47 | AV22: -1652.29 | AW22: -8573.97 | AX22: -1018.13 | AY22: 0 | AZ22: 0 | BA22: -4152.28 | BB22: =SUM(AP22:BA22) -> -17364.88 | BC22: -202.57 | BD22: -4502.57 | BE22: 0 | BF22: 0 | BG22: 0 | BH22: -190.87 | BI22: 0 | BO22: =SUM(BC22:BN22) -> -4896.01
B23: 4020500202 Sales Parts Through Service USED Parts Flat Rate | AP23: 0 | AQ23: 0 | AR23: 0 | AS23: 0 | AT23: 0 | AU23: 0 | AV23: 0 | AW23: 0 | AX23: 0 | AY23: -1701.72 | AZ23: 0 | BA23: 0 | BB23: =SUM(AP23:BA23) -> -1701.72 | BC23: 0 | BD23: 0 | BE23: 0 | BF23: 0 | BG23: 0 | BH23: 0 | BI23: 0 | BO23: =SUM(BC23:BN23) -> 0
B24: 4020800101 Sales Parts Through Counter PEX Product Parts | C24: 0 | D24: -146463.94 | E24: -132542.74 | F24: 0 | G24: -28126.87 | H24: -69398.4 | I24: -954.34 | J24: -76275.5 | K24: -44571.94 | L24: 0 | M24: 0 | N24: -127667.63 | O24: =SUBTOTAL(9,C24:N24) -> -626001.36 | P24: -78516.34 | Q24: -30570.01 | R24: -114206.9 | S24: 0 | T24: -43713.19 | U24: -117856.39 | V24: -259288.66 | W24: -244737.6 | X24: -110060.45 | Y24: -31584.62 | Z24: 0 | AA24: 0 | AB24: =SUM(P24:AA24) -> -1030534.2 | AC24: 0 | AD24: -1554.55 | AE24: 0 | AF24: 0 | AG24: 0 | AH24: 0 | AI24: 0 | AJ24: 0 | AK24: 0 | AL24: 0 | AM24: 0 | AN24: 0 | AO24: =SUM(AC24:AN24) -> -1554.55 | AP24: 0 | AQ24: 0 | AR24: 0 | AS24: 0 | AT24: 0 | AU24: 0 | AV24: 0 | AW24: -120541.99 | AX24: 0 | AY24: -127715.57 | AZ24: -40296.13 | BA24: -49714.79 | BB24: =SUM(AP24:BA24) -> -338268.48 | BC24: -38723.75 | BD24: -328281.16 | BE24: -117641.99 | BF24: 0 | BG24: 0 | BH24: -107312.64 | BI24: -84405.15 | BO24: =SUM(BC24:BN24) -> -676364.69
B25: 4020800102 Sales Parts Through Counter PEX Core Parts | E25: -146097.83 | F25: 0 | G25: -78051.36 | H25: -225704.97 | I25: -5014.74 | J25: -274453.04 | K25: -187389.62 | L25: 0 | M25: 0 | N25: -139899.91 | O25: =SUBTOTAL(9,C25:N25) -> -1056611.5 | P25: -296751.67 | Q25: -87722.95 | R25: -79761.93 | S25: 0 | T25: -137011.11 | U25: -459214.92 | V25: -285787.04 | W25: -194987.98 | X25: -171197.51 | Y25: -91000.64 | Z25: 0 | AA25: 0 | AB25: =SUM(P25:AA25) -> -1803435.7 | AC25: 0 | AD25: -4480.61 | AE25: 0 | AF25: 0 | AG25: 0 | AH25: 0 | AI25: 0 | AJ25: 0 | AK25: 0 | AL25: 0 | AM25: 0 | AN25: 0 | AO25: =SUM(AC25:AN25) -> -4480.61 | AP25: 0 | AQ25: 0 | AR25: 0 | AS25: 0 | AT25: 0 | AU25: 0 | AV25: 0 | AW25: -77387.89 | AX25: 0 | AY25: -115550.41 | AZ25: -93804.87 | BA25: -128383.74 | BB25: =SUM(AP25:BA25) -> -415126.91 | BC25: -160539.47 | BD25: -536484.91 | BE25: -75526.1 | BF25: 0 | BG25: 0 | BH25: -25564.29 | BI25: -108647.07 | BO25: =SUM(BC25:BN25) -> -906761.84
B26: 4020900100 Sales Parts Freight Charges | C26: -1606.18 | D26: 33.87 | E26: -559.24 | F26: 0 | G26: -7534.06 | H26: -5017.58 | I26: -8809.04 | J26: -1976.3 | K26: -25501.38 | L26: -1979.22 | M26: -13400.78 | N26: -5059.83 | O26: =SUBTOTAL(9,C26:N26) -> -71409.74 | P26: -2512.26 | Q26: -4124.26 | R26: -2637.59 | S26: -2490.86 | T26: -5382.71 | U26: -13070.08 | V26: -9445.06 | W26: -1580.52 | X26: -1155.56 | Y26: -2695.67 | Z26: -11384.86 | AA26: -3499.61 | AB26: =SUM(P26:AA26) -> -59979.04 | AC26: -1057.15 | AD26: -2963.04 | AE26: -2809.91 | AF26: 0 | AG26: 0 | AH26: 0 | AI26: -3119.73 | AJ26: -4515.1 | AK26: 0 | AL26: -3231.44 | AM26: 0 | AN26: -1689.1 | AO26: =SUM(AC26:AN26) -> -19385.47 | AP26: 0 | AQ26: 0 | AR26: 0 | AS26: 0 | AT26: 0 | AU26: 0 | AV26: -22565.33 | AW26: -1144.96 | AX26: -3230.02 | AY26: -1790.38 | AZ26: -524.94 | BA26: -1905.65 | BB26: =SUM(AP26:BA26) -> -31161.28 | BC26: -3363.51 | BD26: -3328.96 | BE26: -911.29 | BF26: -3877.9 | BG26: 0 | BH26: -0.49 | BI26: 0 | BO26: =SUM(BC26:BN26) -> -11482.15
B27: 4021000101 Sales Parts Discount TPCP | C27: 12361.59 | D27: 7910.82 | E27: 14657.85 | F27: 12518.9 | G27: 19923.82 | H27: 14121.07 | I27: 13118.59 | J27: 16632.26 | K27: 23059.51 | L27: 23028.07 | M27: 28250.49 | N27: 21187.63 | O27: =SUBTOTAL(9,C27:N27) -> 206770.6 | P27: 15005.41 | Q27: 22721.86 | R27: 13784.98 | S27: 29478 | T27: 32816.67 | U27: 54645.62 | V27: 45858.54 | W27: 15563.63 | X27: 5529.32 | Y27: 15321.41 | Z27: 10925.44 | AA27: 10197.14 | AB27: =SUM(P27:AA27) -> 271848.02 | AC27: 15071.25 | AD27: 13600.84 | AE27: 5104.28 | AF27: 8076.63 | AG27: 10457.46 | AH27: 8971.38 | AI27: 5817.46 | AJ27: 11901.63 | AK27: 7057.07 | AL27: 6233.64 | AM27: 4866.37 | AN27: 8138.19 | AO27: =SUM(AC27:AN27) -> 105296.2 | AP27: 9021.43 | AQ27: 11122.69 | AR27: =VLOOKUP(B27,'[1]Sheet1 (2)'!$B$2:$C$397,2,0) -> 5074.75 | AS27: =VLOOKUP(B27,'[2]Sheet1 (2)'!$B$2:$C$404,2,0) -> 4441.29 | AT27: 9235.4 | AU27: 7939.36 | AV27: 981.06 | AW27: 1405.87 | AX27: 5999.24 | AY27: 6912.83 | AZ27: 13230.5 | BA27: 0 | BB27: =SUM(AP27:BA27) -> 75364.42 | BC27: 0 | BD27: 0 | BE27: 0 | BF27: 0 | BG27: 0 | BH27: 0 | BI27: 0 | BO27: =SUM(BC27:BN27) -> 0
B28: 4021000101 SLS Parts Discount | AP28: 0 | AQ28: 0 | AR28: 0 | AS28: 0 | AT28: 0 | AU28: 0 | AV28: 0 | AW28: 0 | AX28: 0 | AY28: 0 | AZ28: 0 | BA28: 3138.87 | BB28: =SUM(AP28:BA28) -> 3138.87 | BC28: 2783.65 | BD28: 7904.59 | BE28: 2659.14 | BF28: 2498.68 | BG28: 1246.69 | BH28: 5493.79 | BI28: 4707.63 | BO28: =SUM(BC28:BN28) -> 27294.17
B29: 4021000201 Sales PS Parts Discount Thru Service | BC29: 0 | BD29: 0 | BE29: 0 | BF29: 0 | BG29: 0 | BH29: 1189.84 | BI29: 10048.03 | BO29: =SUM(BC29:BN29) -> 11237.87
B30: 4021000202 Sales PS Parts Variance Discount Thru Service | BC30: 0 | BD30: 0 | BE30: 0 | BF30: 0 | BG30: 0 | BH30: -916.48 | BI30: -5122.87 | BO30: =SUM(BC30:BN30) -> -6039.35
B31: 4021400103 Sales Parts PEX Fee | C31: 0 | D31: -9916.38 | E31: -6223.35 | F31: 0 | G31: -2283.41 | H31: -6346.31 | I31: -128.37 | J31: -7542.56 | K31: -4988.42 | L31: 0 | M31: 0 | N31: -5754.14 | O31: =SUBTOTAL(9,C31:N31) -> -43182.94 | P31: -8070.29 | Q31: -2543.94 | R31: -4171.37 | S31: 0 | T31: -3886.54 | U31: -10293.56 | V31: -11608.78 | W31: -9654.85 | X31: -5989.53 | Y31: -2446.92 | Z31: 0 | AA31: 0 | AB31: =SUM(P31:AA31) -> -58665.78 | AC31: 0 | AD31: -129.79 | AE31: 0 | AF31: 0 | AG31: 0 | AH31: 0 | AI31: 0 | AJ31: 0 | AK31: 0 | AL31: 0 | AM31: 0 | AN31: 0 | AO31: =SUM(AC31:AN31) -> -129.79 | AP31: 0 | AQ31: 0 | AR31: 0 | AS31: 0 | AT31: 0 | AU31: 0 | AV31: 0 | AW31: -4256.56 | AX31: 0 | AY31: -5231.53 | AZ31: -2883.89 | BA31: -3830.08 | BB31: =SUM(AP31:BA31) -> -16202.06 | BC31: -4285.22 | BD31: -18597.12 | BE31: -4154.15 | BF31: 0 | BG31: 0 | BH31: -2857.57 | BI31: -4019.3 | BO31: =SUM(BC31:BN31) -> -33913.36
B32: 4021500002 IFRS 15 Preventive Maintenance Parts | AC32: 0 | AD32: 0 | AE32: 0 | AF32: 0 | AG32: 0 | AH32: 0 | AI32: -284.79 | AJ32: 0 | AK32: 0 | AL32: 0 | AM32: 0 | AN32: -847.45 | AO32: =SUM(AC32:AN32) -> -1132.24 | AP32: 0 | AQ32: -1496.38 | AR32: =VLOOKUP(B32,'[1]Sheet1 (2)'!$B$2:$C$397,2,0) -> 0 | AS32: =VLOOKUP(B32,'[2]Sheet1 (2)'!$B$2:$C$404,2,0) -> 0 | AT32: 0 | AU32: 0 | AV32: 0 | AW32: 0 | AX32: 0 | AY32: 0 | AZ32: 0 | BA32: 0 | BB32: =SUM(AP32:BA32) -> -1496.38 | BC32: 0 | BD32: 0 | BE32: 0 | BF32: 0 | BG32: -810.35 | BH32: 0 | BI32: 0 | BO32: =SUM(BC32:BN32) -> -810.35
B33: 4021900101 Sales Parts Discount PSWEB | AC33: 0 | AD33: 0 | AE33: 0 | AF33: 0 | AG33: 0 | AH33: 0 | AI33: 0 | AJ33: 0 | AK33: 35.65 | AL33: 53.56 | AM33: 13.19 | AN33: 23.02 | AO33: =SUM(AC33:AN33) -> 125.42 | AP33: 18.79 | AQ33: 44.24 | AR33: =VLOOKUP(B33,'[1]Sheet1 (2)'!$B$2:$C$397,2,0) -> 141.56 | AS33: =VLOOKUP(B33,'[2]Sheet1 (2)'!$B$2:$C$404,2,0) -> 0 | AT33: 0 | AU33: 0 | AV33: 0 | AW33: 0 | AX33: 0 | AY33: 0.88 | AZ33: 0 | BA33: 0 | BB33: =SUM(AP33:BA33) -> 205.47 | BC33: 0 | BD33: 0 | BE33: 0 | BF33: 26.71 | BG33: 195.29 | BH33: 223.68 | BI33: 136.82 | BO33: =SUM(BC33:BN33) -> 582.5
B34: PARTS | C34: =SUM(C14:C31) -> -4855325.9 | D34: =SUM(D14:D31) -> -4879301.2 | E34: =SUM(E14:E31) -> -5701726 | F34: =SUM(F14:F31) -> -4920050.9 | G34: =SUM(G14:G31) -> -5861700.9 | H34: =SUM(H14:H31) -> -7566765.8 | I34: =SUM(I14:I31) -> -5494331.4 | J34: =SUM(J14:J31) -> -3986195.8 | ... N34: =SUM(N14:N31) -> -11045527 | O34: =SUM(C34:N34) -> -80239911 | P34: =SUM(P14:P31) -> -7393626.5 | Q34: =SUM(Q14:Q31) -> -5214960.2 | R34: =SUM(R14:R31) -> -11286657 | S34: =SUM(S14:S31) -> -6058073.6 | T34: =SUM(T14:T31) -> -8454023.2 | U34: =SUM(U14:U31) -> -7402074.9 | V34: =SUM(V14:V31) -> -5997260.1 | W34: =SUM(W14:W31) -> -6399278 | ... AB34: =SUM(AB14:AB31) -> -80532455 | AC34: =SUM(AC14:AC33) -> -4208704.8 | AD34: =SUM(AD14:AD33) -> -6096921.1 | AE34: =SUM(AE14:AE33) -> -5647105.1 | AF34: =SUM(AF14:AF33) -> -5123737.1 | AG34: =SUM(AG14:AG33) -> -6287411.8 | AH34: =SUM(AH14:AH33) -> -5487696.7 | AI34: =SUM(AI14:AI33) -> -6100174.8 | AJ34: =SUM(AJ14:AJ33) -> -2515899.4 | ... BO34: =SUM(BO14:BO33) -> -27343421
B35: 4030100201 Sales Service Flat Rate Variance Labor | C35: 31846.94 | D35: 59663.84 | E35: 44742.37 | F35: 42026.98 | G35: 48183.68 | H35: 43164.95 | I35: 34372.74 | J35: 23829.84 | K35: 57103.92 | L35: 45849.41 | M35: 77523.22 | N35: 77079.18 | O35: =SUBTOTAL(9,C35:N35) -> 585387.07 | P35: 43908.8 | Q35: 119715.77 | R35: 72926.97 | S35: 72185.61 | T35: 108249.35 | U35: 46936.7 | V35: 51600.81 | W35: 64095.13 | X35: 61696.39 | Y35: 39141.78 | Z35: 92582.77 | AA35: 34358.07 | AB35: =SUM(P35:AA35) -> 807398.15 | AC35: 29745.78 | AD35: 55257.16 | AE35: 97014.8 | AF35: 57182.3 | AG35: 56365.7 | AH35: 33655.21 | AI35: 43873.9 | AJ35: 50375.43 | AK35: 28524.41 | AL35: 17681.36 | AM35: 14770.25 | AN35: 27262.83 | AO35: =SUM(AC35:AN35) -> 511709.13 | AP35: 17613.93 | AQ35: 11656.76 | AR35: =VLOOKUP(B35,'[1]Sheet1 (2)'!$B$2:$C$397,2,0) -> 4358.16 | AS35: =VLOOKUP(B35,'[2]Sheet1 (2)'!$B$2:$C$404,2,0) -> -1291.12 | AT35: 10501.78 | AU35: 6588.53 | AV35: 12745.36 | AW35: 15685.59 | AX35: 5873.45 | AY35: 17945.96 | AZ35: 7166.39 | BA35: 6613.86 | BB35: =SUM(AP35:BA35) -> 115458.65 | BC35: 9814.29 | BD35: 12753.37 | BE35: 12154.83 | BF35: 19206.33 | BG35: 11442.95 | BH35: 4610.83 | BI35: 17761.82 | BO35: =SUM(BC35:BN35) -> 87744.42
B36: 4030100203 Sales Service Flat Rate PO | C36: -31894.21 | D36: -22016.68 | E36: -52919.64 | F36: -12641.32 | G36: -21749.51 | H36: -32159.08 | I36: -13967.74 | J36: -15083.77 | K36: -33449.21 | L36: -14500.52 | M36: -6041.52 | N36: -12749.61 | O36: =SUBTOTAL(9,C36:N36) -> -269172.81 | P36: -32874.71 | Q36: -15225.67 | R36: -14717.32 | S36: -13475.84 | T36: -46575.53 | U36: -29545.3 | V36: -38803.51 | W36: -54144.06 | X36: -199400.81 | Y36: -63183.99 | Z36: -338046.03 | AA36: -151714.25 | AB36: =SUM(P36:AA36) -> -997707.02 | AC36: -167937.03 | AD36: -104356.62 | AE36: -265912.97 | AF36: -61026.2 | AG36: -136315.74 | AH36: -76824.56 | AI36: -149562.52 | AJ36: -52157.69 | AK36: -34385.64 | AL36: -105166.07 | AM36: -69384.34 | AN36: -33909.57 | AO36: =SUM(AC36:AN36) -> -1256938.9 | AP36: -50314.69 | AQ36: -47815.94 | AR36: =VLOOKUP(B36,'[1]Sheet1 (2)'!$B$2:$C$397,2,0) -> -39258.93 | AS36: =VLOOKUP(B36,'[2]Sheet1 (2)'!$B$2:$C$404,2,0) -> -20925.3 | AT36: -27564.71 | AU36: -47839.19 | AV36: -20649.18 | AW36: -34252.04 | AX36: -22267.16 | AY36: -30937.03 | AZ36: -6587.03 | BA36: -14850.79 | BB36: =SUM(AP36:BA36) -> -363261.99 | BC36: -31026.23 | BD36: -7204.93 | BE36: -14873.51 | BF36: -12027.55 | BG36: -26250.2 | BH36: -60172.5 | BI36: -18082.59 | BO36: =SUM(BC36:BN36) -> -169637.51
B37: 4030100204 Sales Service Flat Rate Supplies | C37: -17785.87 | D37: -12577.46 | E37: -16307.3 | F37: -15183.13 | G37: -14338.32 | H37: -15619.6 | I37: -15764.43 | J37: -17881 | K37: -77866.97 | L37: -17190.91 | M37: -15926.47 | N37: -134889.41 | O37: =SUBTOTAL(9,C37:N37) -> -371330.87 | P37: -13117.64 | Q37: -20447.88 | R37: -19643.37 | S37: -12209.82 | T37: -16510.9 | U37: -12897.8 | V37: -19330.15 | W37: -15338.58 | X37: -36634.52 | Y37: -20429.06 | Z37: -14100.55 | AA37: -28071.32 | AB37: =SUM(P37:AA37) -> -228731.59 | AC37: -18715.17 | AD37: -19512.62 | AE37: -21918.62 | AF37: -16822.83 | AG37: -23728.14 | AH37: -15665.56 | AI37: -25787.42 | AJ37: -21644.43 | AK37: -19917.19 | AL37: -11046.31 | AM37: -13789.73 | AN37: -23302.83 | AO37: =SUM(AC37:AN37) -> -231850.85 | AP37: -14557.94 | AQ37: -11299.85 | AR37: =VLOOKUP(B37,'[1]Sheet1 (2)'!$B$2:$C$397,2,0) -> -12595.3 | AS37: =VLOOKUP(B37,'[2]Sheet1 (2)'!$B$2:$C$404,2,0) -> -7720.27 | AT37: -14634.66 | AU37: -12810.19 | AV37: -13826.27 | AW37: -23694.38 | AX37: -9042.42 | AY37: -19405.15 | AZ37: -10440.85 | BA37: -8756.01 | BB37: =SUM(AP37:BA37) -> -158783.29 | BC37: -5068.22 | BD37: -6452.22 | BE37: -14078.82 | BF37: -6231.79 | BG37: -27681.16 | BH37: -21935.28 | BI37: -15849.09 | BO37: =SUM(BC37:BN37) -> -97296.58
B38: 4030100207 Sales Service Flat Rate Labor | C38: -222549.26 | D38: -264855.62 | E38: -340217.35 | F38: -309508.72 | G38: -342248.44 | H38: -371958.97 | I38: -316944.91 | J38: -378600.79 | K38: -384713.05 | L38: -351961.85 | M38: -397561.73 | N38: -484740.4 | O38: =SUBTOTAL(9,C38:N38) -> -4165861.1 | P38: -254050.96 | Q38: -505881.88 | R38: -416477.36 | S38: -294969.41 | T38: -451854.31 | U38: -265682.66 | V38: -328291.83 | W38: -277719.49 | X38: -314272.65 | Y38: -421847.53 | Z38: -371903.91 | AA38: -361777.89 | AB38: =SUM(P38:AA38) -> -4264729.9 | AC38: -262742.52 | AD38: -332131.61 | AE38: -457419.5 | AF38: -226187.86 | AG38: -287418.81 | AH38: -254188.41 | AI38: -296017.72 | AJ38: -378888.77 | AK38: -287651.9 | AL38: -303249.7 | AM38: -220361.47 | AN38: -399454.23 | AO38: =SUM(AC38:AN38) -> -3705712.5 | AP38: -173289.42 | AQ38: -144949.05 | AR38: =VLOOKUP(B38,'[1]Sheet1 (2)'!$B$2:$C$397,2,0) -> -189179.68 | AS38: =VLOOKUP(B38,'[2]Sheet1 (2)'!$B$2:$C$404,2,0) -> -101423.86 | AT38: -220243.71 | AU38: -181794.12 | AV38: -303558.69 | AW38: -274893.71 | AX38: -207164.88 | AY38: -291547.89 | AZ38: -229493.8 | BA38: -231282.8 | BB38: =SUM(AP38:BA38) -> -2548821.6 | BC38: -147581.68 | BD38: -239202 | BE38: -196315.47 | BF38: -229059.36 | BG38: -183935.98 | BH38: -162440.51 | BI38: -275285.37 | BO38: =SUM(BC38:BN38) -> -1433820.4
B39: 4030100208 Sales Service Flat Rate Variance Misc. | C39: 4.93 | D39: 10160.01 | E39: 10899.29 | F39: 0.04 | G39: 1117.82 | H39: -1239.7 | I39: 563.53 | J39: 5962.17 | K39: 53302.79 | L39: 1111.79 | M39: -1.32 | N39: -284.93 | O39: =SUBTOTAL(9,C39:N39) -> 81596.42 | P39: 3361.41 | Q39: 2121.98 | R39: 239.53 | S39: 12027.73 | T39: 43039.79 | U39: 14460.91 | V39: 22587.5 | W39: 10505.94 | X39: 10463.01 | Y39: 19702.51 | Z39: 43023.67 | AA39: 10064.88 | AB39: =SUM(P39:AA39) -> 191598.86 | AC39: 13552.41 | AD39: 10832.3 | AE39: 27141.43 | AF39: 3926.67 | AG39: 11785.81 | AH39: 9395.16 | AI39: 10813.85 | AJ39: 3886.53 | AK39: 10050.22 | AL39: 31572.85 | AM39: 21144.88 | AN39: 7033 | AO39: =SUM(AC39:AN39) -> 161135.11 | AP39: 428.17 | AQ39: 211.46 | AR39: =VLOOKUP(B39,'[1]Sheet1 (2)'!$B$2:$C$397,2,0) -> 8038.69 | AS39: =VLOOKUP(B39,'[2]Sheet1 (2)'!$B$2:$C$404,2,0) -> 6940.56 | AT39: 1445.93 | AU39: -465.37 | AV39: -175.39 | AW39: 520.25 | AX39: -1434.56 | AY39: 1250.24 | AZ39: -925.23 | BA39: -2420.47 | BB39: =SUM(AP39:BA39) -> 13414.28 | BC39: -1245.41 | BD39: -1012.49 | BE39: -902.26 | BF39: -1720.5 | BG39: -1202.64 | BH39: -4528.15 | BI39: -412.53 | BO39: =SUM(BC39:BN39) -> -11023.98
B40: 4030500100 Sales Service SOS Lab Analysist | C40: 0 | E40: -228.71 | F40: -22.86 | G40: 0 | H40: -111.83 | I40: -189.38 | J40: -289.61 | K40: -241.25 | L40: -216.55 | M40: -474.22 | N40: -489.2 | O40: =SUBTOTAL(9,C40:N40) -> -2263.61 | P40: -316.02 | Q40: -294.07 | R40: -704.48 | S40: 0 | T40: -335.27 | U40: -486.56 | V40: -708.1 | W40: -419.71 | X40: 0 | Y40: -332.75 | Z40: -133.01 | AA40: -43.89 | AB40: =SUM(P40:AA40) -> -3773.86 | AC40: -22.34 | AD40: -696.85 | AE40: -57.63 | AF40: -437.84 | AG40: -344.59 | AH40: -10.96 | AI40: -57.55 | AJ40: 0 | AK40: 0 | AL40: -93.83 | AM40: -11.23 | AN40: 0 | AO40: =SUM(AC40:AN40) -> -1732.82 | AP40: 0 | AQ40: -202.21 | AR40: =VLOOKUP(B40,'[1]Sheet1 (2)'!$B$2:$C$397,2,0) -> -541.46 | AS40: =VLOOKUP(B40,'[2]Sheet1 (2)'!$B$2:$C$404,2,0) -> -296.63 | AT40: -205.66 | AU40: -120.1 | AV40: -556.87 | AW40: 0 | AX40: -113.59 | AY40: -284.47 | AZ40: -96.25 | BA40: -385.64 | BB40: =SUM(AP40:BA40) -> -2802.88 | BC40: -381.35 | BD40: -378.52 | BE40: -28.11 | BF40: -107.04 | BG40: -109.46 | BH40: -162.09 | BI40: -76.43 | BO40: =SUM(BC40:BN40) -> -1243
B41: 4030500107 Sales Service SOS Lab Actual Discount | BC41: 0 | BD41: 0 | BE41: 0.23 | BF41: 0 | BG41: 0.8 | BH41: 0 | BI41: 0 | BO41: =SUM(BC41:BN41) -> 1.03
...

Sheet JAN 22
A1: Financial Statement Item | B1: Text for B/S P&L item | C1: Total of reporting period | D1: Total of the comparison period | E1: Absolute difference | F1: Percentage difference
A2: 1000000 | B2: A S S E T S | C2: 0 | D2: 0 | E2: 0 | F2: =VLOOKUP(B2,'Balance Sheet'!#REF!,2,0) -> #REF!
A3: 1000000 | B3: = = = = = = | C3: 0 | D3: 0 | E3: 0 | F3: =VLOOKUP(B3,'Balance Sheet'!#REF!,2,0) -> #REF!
A4: 10101 | B4: 1011100380 PettyCash IDR SANGATTA | C4: 329.08 | D4: 329.08 | E4: 0 | F4: =VLOOKUP(B4,'Balance Sheet'!#REF!,2,0) -> #REF!
A5: 10101 | B5: 1016109751 Bank IDR Mandiri 1480004169325 MB-SANGATA_COL | C5: 610.44 | D5: 610.44 | E5: 0 | F5: =VLOOKUP(B5,'Balance Sheet'!#REF!,2,0) -> #REF!
A6: 10101 | B6: 1016109761 Bank IDR Mandiri 1480004169309 MB-SANGATA_OPR | C6: 27542.03 | D6: 27542.03 | E6: 0 | F6: =VLOOKUP(B6,'Balance Sheet'!#REF!,2,0) -> #REF!
A7: 10101 | B7: 1016109769 Bank IDR Mandiri 1480004169309 FxV-SANGATA_OPR | C7: -23245.09 | D7: -23245.09 | E7: 0 | F7: =VLOOKUP(B7,'Balance Sheet'!#REF!,2,0) -> #REF!
A8: 10101 | B8: 1016162071 Bank IDR Mandiri 148-001-687266-8 MB SGT | C8: 68.59 | D8: 68.59 | E8: 0 | F8: =VLOOKUP(B8,'Balance Sheet'!#REF!,2,0) -> #REF!
A9: 10101 | B9: 1016162079 Bank IDR Mandiri 148-001-687266-8 FxV SGT | C9: 2.69 | D9: 2.69 | E9: 0 | F9: =VLOOKUP(B9,'Balance Sheet'!#REF!,2,0) -> #REF!
A10: 10101 | C10: 5307.74 | D10: 5307.74 | E10: 0 | F10: =VLOOKUP(B10,'Balance Sheet'!#REF!,2,0) -> #REF!
A11: 101 | C11: 5307.74 | D11: 5307.74 | E11: 0 | F11: =VLOOKUP(B11,'Balance Sheet'!#REF!,2,0) -> #REF!
A12: 10201 | B12: 1110101000 AR Gross Trade 3rd Party | C12: 13061995 | D12: 13061995 | E12: 0 | F12: =VLOOKUP(B12,'Balance Sheet'!#REF!,2,0) -> #REF!
A13: 10201 | B13: 1110101009 AR Gross Trade 3rd Party FxV | C13: -65935.64 | D13: -65935.64 | E13: 0 | F13: =VLOOKUP(B13,'Balance Sheet'!#REF!,2,0) -> #REF!
A14: 10201 | B14: 1110102000 AR Gross Trade Rel Party | C14: 1608482 | D14: 1608482 | E14: 0 | F14: =VLOOKUP(B14,'Balance Sheet'!#REF!,2,0) -> #REF!
A15: 10201 | B15: 1110102009 AR Gross Trade Rel Party FxV | C15: -100611.35 | D15: -100611.35 | E15: 0 | F15: =VLOOKUP(B15,'Balance Sheet'!#REF!,2,0) -> #REF!
A16: 10201 | C16: 14503930 | D16: 14503930 | E16: 0 | F16: =VLOOKUP(B16,'Balance Sheet'!#REF!,2,0) -> #REF!
A17: 10202 | B17: 1120101000 AR Gross Trade 3rd Party Allowance | C17: -38389.61 | D17: -38389.61 | E17: 0 | F17: =VLOOKUP(B17,'Balance Sheet'!#REF!,2,0) -> #REF!
A18: 10202 | C18: -38389.61 | D18: -38389.61 | E18: 0 | F18: =VLOOKUP(B18,'Balance Sheet'!#REF!,2,0) -> #REF!
A19: 102 | C19: 14465541 | D19: 14465541 | E19: 0 | F19: =VLOOKUP(B19,'Balance Sheet'!#REF!,2,0) -> #REF!
A20: 10301 | B20: 1211101000 AR Claim Warranty Pending 3rd Party | C20: 0.01 | D20: 0.01 | E20: 0 | F20: =VLOOKUP(B20,'Balance Sheet'!#REF!,2,0) -> #REF!
A21: 10301 | B21: 1211201311 AR Claim TWLBR | C21: 2588.06 | D21: 2588.06 | E21: 0 | F21: =VLOOKUP(B21,'Balance Sheet'!#REF!,2,0) -> #REF!
A22: 10301 | B22: 1211301000 AR Claim Warranty Claim 3rd Party | C22: 0.01 | D22: 0.01 | E22: 0 | F22: =VLOOKUP(B22,'Balance Sheet'!#REF!,2,0) -> #REF!
A23: 10301 | B23: 1211301001 AR Claim Warranty Claim 3rd Party New | C23: 25403.68 | D23: 25403.68 | E23: 0 | F23: =VLOOKUP(B23,'Balance Sheet'!#REF!,2,0) -> #REF!
A24: 10301 | B24: 1211401001 AR Claim 3rd Party Goodwill (New Acct) | C24: 10538.29 | D24: 10538.29 | E24: 0 | F24: =VLOOKUP(B24,'Balance Sheet'!#REF!,2,0) -> #REF!
A25: 10301 | B25: 1211401310 AR Claim Warranty Claim-Goodwill 3rd Party OEM | C25: 19.35 | D25: 19.35 | E25: 0 | F25: =VLOOKUP(B25,'Balance Sheet'!#REF!,2,0) -> #REF!
A26: 10301 | C26: 38549.4 | D26: 38549.4 | E26: 0 | F26: =VLOOKUP(B26,'Balance Sheet'!#REF!,2,0) -> #REF!
A27: 10302 | B27: 1212001010 AR Claim 3rd Party CAT Parts Core | C27: 17751.83 | D27: 17751.83 | E27: 0 | F27: =VLOOKUP(B27,'Balance Sheet'!#REF!,2,0) -> #REF!
A28: 10302 | C28: 17751.83 | D28: 17751.83 | E28: 0 | F28: =VLOOKUP(B28,'Balance Sheet'!#REF!,2,0) -> #REF!
A29: 10306 | B29: 1110101230 AR Gross Trade 3rd Party Art23 | C29: 55428.1 | D29: 55428.1 | E29: 0 | F29: =VLOOKUP(B29,'Balance Sheet'!#REF!,2,0) -> #REF!
A30: 10306 | B30: 1110101239 AR Gross Trade 3rd Party Art23 FxV | C30: -238.21 | D30: -238.21 | E30: 0 | F30: =VLOOKUP(B30,'Balance Sheet'!#REF!,2,0) -> #REF!
A31: 10306 | B31: 1110102230 AR Gross Trade Rel Party Art23 | C31: 601.35 | D31: 601.35 | E31: 0 | F31: =VLOOKUP(B31,'Balance Sheet'!#REF!,2,0) -> #REF!
A32: 10306 | B32: 1110102239 AR Gross Trade Rel Party Art23 FxV | C32: -4.27 | D32: -4.27 | E32: 0 | F32: =VLOOKUP(B32,'Balance Sheet'!#REF!,2,0) -> #REF!
A33: 10306 | B33: 1110181000 AR Gross Others Project System Over Under | C33: 2597.52 | D33: 2597.52 | E33: 0 | F33: =VLOOKUP(B33,'Balance Sheet'!#REF!,2,0) -> #REF!
A34: 10306 | B34: 1110202000 AR Gross Non Trade Rel Party | C34: 2611.46 | D34: 2611.46 | E34: 0 | F34: =VLOOKUP(B34,'Balance Sheet'!#REF!,2,0) -> #REF!
A35: 10306 | B35: 1110202009 AR Gross Non Trade Rel Party FxV | C35: -5.3 | D35: -5.3 | E35: 0 | F35: =VLOOKUP(B35,'Balance Sheet'!#REF!,2,0) -> #REF!
A36: 10306 | B36: 1216001020 AR Claim 3rd Party CAT PSDN | C36: 7323.97 | D36: 7323.97 | E36: 0 | F36: =VLOOKUP(B36,'Balance Sheet'!#REF!,2,0) -> #REF!
A37: 10306 | B37: 1219301000 AR Claim Others 3rd Party | C37: 2618.36 | D37: 2618.36 | E37: 0 | F37: =VLOOKUP(B37,'Balance Sheet'!#REF!,2,0) -> #REF!
A38: 10306 | B38: 1219302070 AR Claim Others Rel Party CKB | C38: 40.38 | D38: 40.38 | E38: 0 | F38: =VLOOKUP(B38,'Balance Sheet'!#REF!,2,0) -> #REF!
A39: 10306 | C39: 70973.36 | D39: 70973.36 | E39: 0 | F39: =VLOOKUP(B39,'Balance Sheet'!#REF!,2,0) -> #REF!
A40: 103 | C40: 127274.59 | D40: 127274.59 | E40: 0 | F40: =VLOOKUP(B40,'Balance Sheet'!#REF!,2,0) -> #REF!
...

Sheet FEB 22
A1: Financial Statement Item | B1: Text for B/S P&L item | C1: Total of reporting period | D1: Total of the comparison period | E1: Absolute difference | F1: Percentage difference | G1: A
A2: 1000000 | B2: A S S E T S | C2: 0 | D2: 0 | E2: 0
A3: 1000000 | B3: = = = = = = | C3: 0 | D3: 0 | E3: 0
A4: 10101 | B4: 1011100380 PettyCash IDR SANGATTA | C4: 329.08 | D4: 329.08 | E4: 0 | F4: 0.0 | G4: =VLOOKUP(B4,'Profit & Loss'!$B$3:$C$390,2,0) -> #N/A
A5: 10101 | B5: 1016109751 Bank IDR Mandiri 1480004169325 MB-SANGATA_COL | C5: 610.44 | D5: 610.44 | E5: 0 | F5: 0.0 | G5: =VLOOKUP(B5,'Profit & Loss'!$B$3:$C$390,2,0) -> #N/A
A6: 10101 | B6: 1016109761 Bank IDR Mandiri 1480004169309 MB-SANGATA_OPR | C6: 27836.1 | D6: 27542.03 | E6: 294.07 | F6: 1.1 | G6: =VLOOKUP(B6,'Profit & Loss'!$B$3:$C$390,2,0) -> #N/A
A7: 10101 | B7: 1016109769 Bank IDR Mandiri 1480004169309 FxV-SANGATA_OPR | C7: -23238.24 | D7: -23245.09 | E7: 6.85 | F7: 0.0 | G7: =VLOOKUP(B7,'Profit & Loss'!$B$3:$C$390,2,0) -> #N/A
A8: 10101 | B8: 1016162071 Bank IDR Mandiri 148-001-687266-8 MB SGT | C8: 68.59 | D8: 68.59 | E8: 0 | F8: 0.0 | G8: =VLOOKUP(B8,'Profit & Loss'!$B$3:$C$390,2,0) -> #N/A
A9: 10101 | B9: 1016162079 Bank IDR Mandiri 148-001-687266-8 FxV SGT | C9: 2.73 | D9: 2.69 | E9: 0.04 | F9: 1.5 | G9: =VLOOKUP(B9,'Profit & Loss'!$B$3:$C$390,2,0) -> #N/A
A10: 10101 | C10: 5608.7 | D10: 5307.74 | E10: 300.96 | F10: 5.7
A11: 101 | C11: 5608.7 | D11: 5307.74 | E11: 300.96 | F11: 5.7
A12: 10201 | B12: 1110101000 AR Gross Trade 3rd Party | C12: 14048204 | D12: 13061995 | E12: 986208.62 | F12: 7.6 | G12: =VLOOKUP(B12,'Profit & Loss'!$B$3:$C$390,2,0) -> #N/A
A13: 10201 | B13: 1110101009 AR Gross Trade 3rd Party FxV | C13: -25280.23 | D13: -65935.64 | E13: 40655.41 | F13: 61.7 | G13: =VLOOKUP(B13,'Profit & Loss'!$B$3:$C$390,2,0) -> #N/A
A14: 10201 | B14: 1110102000 AR Gross Trade Rel Party | C14: 1608482 | D14: 1608482 | E14: 0 | F14: 0.0 | G14: =VLOOKUP(B14,'Profit & Loss'!$B$3:$C$390,2,0) -> #N/A
A15: 10201 | B15: 1110102009 AR Gross Trade Rel Party FxV | C15: -99743.94 | D15: -100611.35 | E15: 867.41 | F15: 0.9 | G15: =VLOOKUP(B15,'Profit & Loss'!$B$3:$C$390,2,0) -> #N/A
A16: 10201 | C16: 15531662 | D16: 14503930 | E16: 1027731.4 | F16: 7.1
A17: 10202 | B17: 1120101000 AR Gross Trade 3rd Party Allowance | C17: -41048.25 | D17: -38389.61 | E17: -2658.64 | F17: 6.9- | G17: =VLOOKUP(B17,'Profit & Loss'!$B$3:$C$390,2,0) -> #N/A
A18: 10202 | C18: -41048.25 | D18: -38389.61 | E18: -2658.64 | F18: 6.9-
A19: 102 | C19: 15490614 | D19: 14465541 | E19: 1025072.8 | F19: 7.1
A20: 10301 | B20: 1211101000 AR Claim Warranty Pending 3rd Party | C20: 0.01 | D20: 0.01 | E20: 0 | F20: 0.0 | G20: =VLOOKUP(B20,'Profit & Loss'!$B$3:$C$390,2,0) -> #N/A
A21: 10301 | B21: 1211201311 AR Claim TWLBR | C21: 6118.96 | D21: 2588.06 | E21: 3530.9 | F21: 136.4 | G21: =VLOOKUP(B21,'Profit & Loss'!$B$3:$C$390,2,0) -> #N/A
A22: 10301 | B22: 1211301000 AR Claim Warranty Claim 3rd Party | C22: 0.01 | D22: 0.01 | E22: 0 | F22: 0.0 | G22: =VLOOKUP(B22,'Profit & Loss'!$B$3:$C$390,2,0) -> #N/A
A23: 10301 | B23: 1211301001 AR Claim Warranty Claim 3rd Party New | C23: 10131.29 | D23: 25403.68 | E23: -15272.39 | F23: 60.1- | G23: =VLOOKUP(B23,'Profit & Loss'!$B$3:$C$390,2,0) -> #N/A
A24: 10301 | B24: 1211401001 AR Claim 3rd Party Goodwill (New Acct) | C24: 14529.03 | D24: 10538.29 | E24: 3990.74 | F24: 37.9 | G24: =VLOOKUP(B24,'Profit & Loss'!$B$3:$C$390,2,0) -> #N/A
A25: 10301 | B25: 1211401310 AR Claim Warranty Claim-Goodwill 3rd Party OEM | C25: 19.35 | D25: 19.35 | E25: 0 | F25: 0.0 | G25: =VLOOKUP(B25,'Profit & Loss'!$B$3:$C$390,2,0) -> #N/A
A26: 10301 | C26: 30798.65 | D26: 38549.4 | E26: -7750.75 | F26: 20.1-
A27: 10302 | B27: 1212001010 AR Claim 3rd Party CAT Parts Core | C27: 6663.53 | D27: 17751.83 | E27: -11088.3 | F27: 62.5- | G27: =VLOOKUP(B27,'Profit & Loss'!$B$3:$C$390,2,0) -> #N/A
A28: 10302 | C28: 6663.53 | D28: 17751.83 | E28: -11088.3 | F28: 62.5-
A29: 10306 | B29: 1110101230 AR Gross Trade 3rd Party Art23 | C29: 51364.45 | D29: 55428.1 | E29: -4063.65 | F29: 7.3- | G29: =VLOOKUP(B29,'Profit & Loss'!$B$3:$C$390,2,0) -> #N/A
A30: 10306 | B30: 1110101239 AR Gross Trade 3rd Party Art23 FxV | C30: -95.7 | D30: -238.21 | E30: 142.51 | F30: 59.8 | G30: =VLOOKUP(B30,'Profit & Loss'!$B$3:$C$390,2,0) -> #N/A
A31: 10306 | B31: 1110102230 AR Gross Trade Rel Party Art23 | C31: 0 | D31: 601.35 | E31: -601.35 | F31: 100.0- | G31: =VLOOKUP(B31,'Profit & Loss'!$B$3:$C$390,2,0) -> #N/A
A32: 10306 | B32: 1110102239 AR Gross Trade Rel Party Art23 FxV | C32: 0 | D32: -4.27 | E32: 4.27 | F32: 100.0 | G32: =VLOOKUP(B32,'Profit & Loss'!$B$3:$C$390,2,0) -> #N/A
A33: 10306 | B33: 1110181000 AR Gross Others Project System Over Under | C33: 2597.52 | D33: 2597.52 | E33: 0 | F33: 0.0 | G33: =VLOOKUP(B33,'Profit & Loss'!$B$3:$C$390,2,0) -> #N/A
A34: 10306 | B34: 1110201000 AR Gross Non Trade 3rd Party | C34: -216227.47 | D34: 0 | E34: -216227.47 | G34: =VLOOKUP(B34,'Profit & Loss'!$B$3:$C$390,2,0) -> #N/A
A35: 10306 | B35: 1110201009 AR Gross Non Trade 3rd Party FxV | C35: 149.64 | D35: 0 | E35: 149.64 | G35: =VLOOKUP(B35,'Profit & Loss'!$B$3:$C$390,2,0) -> #N/A
A36: 10306 | B36: 1110202000 AR Gross Non Trade Rel Party | C36: 0 | D36: 2611.46 | E36: -2611.46 | F36: 100.0- | G36: =VLOOKUP(B36,'Profit & Loss'!$B$3:$C$390,2,0) -> #N/A
A37: 10306 | B37: 1110202009 AR Gross Non Trade Rel Party FxV | C37: 0 | D37: -5.3 | E37: 5.3 | F37: 100.0 | G37: =VLOOKUP(B37,'Profit & Loss'!$B$3:$C$390,2,0) -> #N/A
A38: 10306 | B38: 1216001020 AR Claim 3rd Party CAT PSDN | C38: -1319.57 | D38: 7323.97 | E38: -8643.54 | F38: 118.0- | G38: =VLOOKUP(B38,'Profit & Loss'!$B$3:$C$390,2,0) -> #N/A
A39: 10306 | B39: 1219301000 AR Claim Others 3rd Party | C39: 2971.13 | D39: 2618.36 | E39: 352.77 | F39: 13.5 | G39: =VLOOKUP(B39,'Profit & Loss'!$B$3:$C$390,2,0) -> #N/A
A40: 10306 | B40: 1219302070 AR Claim Others Rel Party CKB | C40: 40.25 | D40: 40.38 | E40: -0.13 | F40: 0.3- | G40: =VLOOKUP(B40,'Profit & Loss'!$B$3:$C$390,2,0) -> #N/A
...

Sheet MAR 22
A1: Financial Statement Item | B1: Text for B/S P&L item | C1: Total of reporting period | D1: Total of the comparison period | E1: Absolute difference | F1: Percentage difference | G1: A
A2: 1000000 | B2: A S S E T S | C2: 0 | D2: 0 | E2: 0 | G2: =VLOOKUP(B2,'Profit & Loss'!$B$3:$C$390,2,0) -> #N/A
A3: 1000000 | B3: = = = = = = | C3: 0 | D3: 0 | E3: 0 | G3: =VLOOKUP(B3,'Profit & Loss'!$B$3:$C$390,2,0) -> #N/A
A4: 10101 | B4: 1011100380 PettyCash IDR SANGATTA | C4: 329.08 | D4: 329.08 | E4: 0 | F4: 0.0 | G4: =VLOOKUP(B4,'Profit & Loss'!$B$3:$C$390,2,0) -> #N/A
A5: 10101 | B5: 1016109751 Bank IDR Mandiri 1480004169325 MB-SANGATA_COL | C5: 610.44 | D5: 610.44 | E5: 0 | F5: 0.0 | G5: =VLOOKUP(B5,'Profit & Loss'!$B$3:$C$390,2,0) -> #N/A
A6: 10101 | B6: 1016109761 Bank IDR Mandiri 1480004169309 MB-SANGATA_OPR | C6: 26519.23 | D6: 27836.1 | E6: -1316.87 | F6: 4.7- | G6: =VLOOKUP(B6,'Profit & Loss'!$B$3:$C$390,2,0) -> #N/A
A7: 10101 | B7: 1016109769 Bank IDR Mandiri 1480004169309 FxV-SANGATA_OPR | C7: -23252.66 | D7: -23238.24 | E7: -14.42 | F7: 0.1- | G7: =VLOOKUP(B7,'Profit & Loss'!$B$3:$C$390,2,0) -> #N/A
A8: 10101 | B8: 1016162071 Bank IDR Mandiri 148-001-687266-8 MB SGT | C8: 68.59 | D8: 68.59 | E8: 0 | F8: 0.0 | G8: =VLOOKUP(B8,'Profit & Loss'!$B$3:$C$390,2,0) -> #N/A
A9: 10101 | B9: 1016162079 Bank IDR Mandiri 148-001-687266-8 FxV SGT | C9: 2.84 | D9: 2.73 | E9: 0.11 | F9: 4.0 | G9: =VLOOKUP(B9,'Profit & Loss'!$B$3:$C$390,2,0) -> #N/A
A10: 10101 | C10: 4277.52 | D10: 5608.7 | E10: -1331.18 | F10: 23.7- | G10: =VLOOKUP(B10,'Profit & Loss'!$B$3:$C$390,2,0) -> #N/A
A11: 101 | C11: 4277.52 | D11: 5608.7 | E11: -1331.18 | F11: 23.7- | G11: =VLOOKUP(B11,'Profit & Loss'!$B$3:$C$390,2,0) -> #N/A
A12: 10201 | B12: 1110101000 AR Gross Trade 3rd Party | C12: 13924123 | D12: 14048204 | E12: -124080.96 | F12: 0.9- | G12: =VLOOKUP(B12,'Profit & Loss'!$B$3:$C$390,2,0) -> #N/A
A13: 10201 | B13: 1110101009 AR Gross Trade 3rd Party FxV | C13: 10113.67 | D13: -25280.23 | E13: 35393.9 | F13: 140.0 | G13: =VLOOKUP(B13,'Profit & Loss'!$B$3:$C$390,2,0) -> #N/A
A14: 10201 | B14: 1110102000 AR Gross Trade Rel Party | C14: 1601828.4 | D14: 1608482 | E14: -6653.55 | F14: 0.4- | G14: =VLOOKUP(B14,'Profit & Loss'!$B$3:$C$390,2,0) -> #N/A
A15: 10201 | B15: 1110102009 AR Gross Trade Rel Party FxV | C15: -97348.32 | D15: -99743.94 | E15: 2395.62 | F15: 2.4 | G15: =VLOOKUP(B15,'Profit & Loss'!$B$3:$C$390,2,0) -> #N/A
A16: 10201 | C16: 15438717 | D16: 15531662 | E16: -92944.99 | F16: 0.6- | G16: =VLOOKUP(B16,'Profit & Loss'!$B$3:$C$390,2,0) -> #N/A
A17: 10202 | B17: 1120101000 AR Gross Trade 3rd Party Allowance | C17: -40127.62 | D17: -41048.25 | E17: 920.63 | F17: 2.2 | G17: =VLOOKUP(B17,'Profit & Loss'!$B$3:$C$390,2,0) -> #N/A
A18: 10202 | C18: -40127.62 | D18: -41048.25 | E18: 920.63 | F18: 2.2 | G18: =VLOOKUP(B18,'Profit & Loss'!$B$3:$C$390,2,0) -> #N/A
A19: 102 | C19: 15398589 | D19: 15490614 | E19: -92024.36 | F19: 0.6- | G19: =VLOOKUP(B19,'Profit & Loss'!$B$3:$C$390,2,0) -> #N/A
A20: 10301 | B20: 1211101000 AR Claim Warranty Pending 3rd Party | C20: 0.01 | D20: 0.01 | E20: 0 | F20: 0.0 | G20: =VLOOKUP(B20,'Profit & Loss'!$B$3:$C$390,2,0) -> #N/A
A21: 10301 | B21: 1211201311 AR Claim TWLBR | C21: 42291.62 | D21: 6118.96 | E21: 36172.66 | F21: 591.2 | G21: =VLOOKUP(B21,'Profit & Loss'!$B$3:$C$390,2,0) -> #N/A
A22: 10301 | B22: 1211301000 AR Claim Warranty Claim 3rd Party | C22: 0.01 | D22: 0.01 | E22: 0 | F22: 0.0 | G22: =VLOOKUP(B22,'Profit & Loss'!$B$3:$C$390,2,0) -> #N/A
A23: 10301 | B23: 1211301001 AR Claim Warranty Claim 3rd Party New | C23: 27128.57 | D23: 10131.29 | E23: 16997.28 | F23: 167.8 | G23: =VLOOKUP(B23,'Profit & Loss'!$B$3:$C$390,2,0) -> #N/A
A24: 10301 | B24: 1211401001 AR Claim 3rd Party Goodwill (New Acct) | C24: 46253.61 | D24: 14529.03 | E24: 31724.58 | F24: 218.4 | G24: =VLOOKUP(B24,'Profit & Loss'!$B$3:$C$390,2,0) -> #N/A
A25: 10301 | B25: 1211401310 AR Claim Warranty Claim-Goodwill 3rd Party OEM | C25: 19.35 | D25: 19.35 | E25: 0 | F25: 0.0 | G25: =VLOOKUP(B25,'Profit & Loss'!$B$3:$C$390,2,0) -> #N/A
A26: 10301 | C26: 115693.17 | D26: 30798.65 | E26: 84894.52 | F26: 275.6 | G26: =VLOOKUP(B26,'Profit & Loss'!$B$3:$C$390,2,0) -> #N/A
A27: 10302 | B27: 1212001010 AR Claim 3rd Party CAT Parts Core | C27: -7566.42 | D27: 6663.53 | E27: -14229.95 | F27: 213.5- | G27: =VLOOKUP(B27,'Profit & Loss'!$B$3:$C$390,2,0) -> #N/A
A28: 10302 | C28: -7566.42 | D28: 6663.53 | E28: -14229.95 | F28: 213.5- | G28: =VLOOKUP(B28,'Profit & Loss'!$B$3:$C$390,2,0) -> #N/A
A29: 10306 | B29: 1110101230 AR Gross Trade 3rd Party Art23 | C29: 67008.31 | D29: 51364.45 | E29: 15643.86 | F29: 30.5 | G29: =VLOOKUP(B29,'Profit & Loss'!$B$3:$C$390,2,0) -> #N/A
A30: 10306 | B30: 1110101239 AR Gross Trade 3rd Party Art23 FxV | C30: 14.94 | D30: -95.7 | E30: 110.64 | F30: 115.6 | G30: =VLOOKUP(B30,'Profit & Loss'!$B$3:$C$390,2,0) -> #N/A
A31: 10306 | B31: 1110102230 AR Gross Trade Rel Party Art23 | C31: 277.08 | D31: 0 | E31: 277.08 | G31: =VLOOKUP(B31,'Profit & Loss'!$B$3:$C$390,2,0) -> #N/A
A32: 10306 | B32: 1110102239 AR Gross Trade Rel Party Art23 FxV | C32: 1.19 | D32: 0 | E32: 1.19 | G32: =VLOOKUP(B32,'Profit & Loss'!$B$3:$C$390,2,0) -> #N/A
A33: 10306 | B33: 1110181000 AR Gross Others Project System Over Under | C33: 2597.52 | D33: 2597.52 | E33: 0 | F33: 0.0 | G33: =VLOOKUP(B33,'Profit & Loss'!$B$3:$C$390,2,0) -> #N/A
A34: 10306 | B34: 1110201000 AR Gross Non Trade 3rd Party | C34: 0 | D34: -216227.47 | E34: 216227.47 | F34: 100.0 | G34: =VLOOKUP(B34,'Profit & Loss'!$B$3:$C$390,2,0) -> #N/A
A35: 10306 | B35: 1110201009 AR Gross Non Trade 3rd Party FxV | C35: 0 | D35: 149.64 | E35: -149.64 | F35: 100.0- | G35: =VLOOKUP(B35,'Profit & Loss'!$B$3:$C$390,2,0) -> #N/A
A36: 10306 | B36: 1216001020 AR Claim 3rd Party CAT PSDN | C36: 348.54 | D36: -1319.57 | E36: 1668.11 | F36: 126.4 | G36: =VLOOKUP(B36,'Profit & Loss'!$B$3:$C$390,2,0) -> #N/A
A37: 10306 | B37: 1219301000 AR Claim Others 3rd Party | C37: 2821.42 | D37: 2971.13 | E37: -149.71 | F37: 5.0- | G37: =VLOOKUP(B37,'Profit & Loss'!$B$3:$C$390,2,0) -> #N/A
A38: 10306 | B38: 1219301009 AR Claim Others 3rd Party FxV | C38: -0.35 | D38: 0 | E38: -0.35 | G38: =VLOOKUP(B38,'Profit & Loss'!$B$3:$C$390,2,0) -> #N/A
A39: 10306 | B39: 1219302070 AR Claim Others Rel Party CKB | C39: 39.9 | D39: 40.25 | E39: -0.35 | F39: 0.9- | G39: =VLOOKUP(B39,'Profit & Loss'!$B$3:$C$390,2,0) -> #N/A
A40: 10306 | C40: 73108.55 | D40: -160519.75 | E40: 233628.3 | F40: 145.5 | G40: =VLOOKUP(B40,'Profit & Loss'!$B$3:$C$390,2,0) -> #N/A
...

Sheet APR 22
A1: Financial Statement Item | B1: Text for B/S P&L item | C1: Total of reporting period | D1: Total of the comparison period | E1: Absolute difference | F1: Percentage difference | G1: A
A2: 1000000 | B2: A S S E T S | C2: 0 | D2: 0 | E2: 0 | G2: =VLOOKUP(B2,'Profit & Loss'!$B$3:$C$390,2,0) -> #N/A
A3: 1000000 | B3: = = = = = = | C3: 0 | D3: 0 | E3: 0 | G3: =VLOOKUP(B3,'Profit & Loss'!$B$3:$C$390,2,0) -> #N/A
A4: 10101 | B4: 1011100380 PettyCash IDR SANGATTA | C4: 329.08 | D4: 329.08 | E4: 0 | F4: 0.0 | G4: =VLOOKUP(B4,'Profit & Loss'!$B$3:$C$390,2,0) -> #N/A
A5: 10101 | B5: 1016109751 Bank IDR Mandiri 1480004169325 MB-SANGATA_COL | C5: 610.44 | D5: 610.44 | E5: 0 | F5: 0.0 | G5: =VLOOKUP(B5,'Profit & Loss'!$B$3:$C$390,2,0) -> #N/A
A6: 10101 | B6: 1016109761 Bank IDR Mandiri 1480004169309 MB-SANGATA_OPR | C6: 23494.19 | D6: 26519.23 | E6: -3025.04 | F6: 11.4- | G6: =VLOOKUP(B6,'Profit & Loss'!$B$3:$C$390,2,0) -> #N/A
A7: 10101 | B7: 1016109769 Bank IDR Mandiri 1480004169309 FxV-SANGATA_OPR | C7: -23412.73 | D7: -23252.66 | E7: -160.07 | F7: 0.7- | G7: =VLOOKUP(B7,'Profit & Loss'!$B$3:$C$390,2,0) -> #N/A
A8: 10101 | B8: 1016162071 Bank IDR Mandiri 148-001-687266-8 MB SGT | C8: 68.6 | D8: 68.59 | E8: 0.01 | F8: 0.0 | G8: =VLOOKUP(B8,'Profit & Loss'!$B$3:$C$390,2,0) -> #N/A
A9: 10101 | B9: 1016162079 Bank IDR Mandiri 148-001-687266-8 FxV SGT | C9: 2.49 | D9: 2.84 | E9: -0.35 | F9: 12.3- | G9: =VLOOKUP(B9,'Profit & Loss'!$B$3:$C$390,2,0) -> #N/A
A10: 10101 | C10: 1092.07 | D10: 4277.52 | E10: -3185.45 | F10: 74.5- | G10: =VLOOKUP(B10,'Profit & Loss'!$B$3:$C$390,2,0) -> #N/A
A11: 101 | C11: 1092.07 | D11: 4277.52 | E11: -3185.45 | F11: 74.5- | G11: =VLOOKUP(B11,'Profit & Loss'!$B$3:$C$390,2,0) -> #N/A
A12: 10201 | B12: 1110101000 AR Gross Trade 3rd Party | C12: 13702348 | D12: 13924123 | E12: -221775.23 | F12: 1.6- | G12: =VLOOKUP(B12,'Profit & Loss'!$B$3:$C$390,2,0) -> #N/A
A13: 10201 | B13: 1110101009 AR Gross Trade 3rd Party FxV | C13: -35312.69 | D13: 10113.67 | E13: -45426.36 | F13: 449.2- | G13: =VLOOKUP(B13,'Profit & Loss'!$B$3:$C$390,2,0) -> #N/A
A14: 10201 | B14: 1110102000 AR Gross Trade Rel Party | C14: 1601828.4 | D14: 1601828.4 | E14: 0 | F14: 0.0 | G14: =VLOOKUP(B14,'Profit & Loss'!$B$3:$C$390,2,0) -> #N/A
A15: 10201 | B15: 1110102009 AR Gross Trade Rel Party FxV | C15: -104472.47 | D15: -97348.32 | E15: -7124.15 | F15: 7.3- | G15: =VLOOKUP(B15,'Profit & Loss'!$B$3:$C$390,2,0) -> #N/A
A16: 10201 | C16: 15164391 | D16: 15438717 | E16: -274325.74 | F16: 1.8- | G16: =VLOOKUP(B16,'Profit & Loss'!$B$3:$C$390,2,0) -> #N/A
A17: 10202 | B17: 1120101000 AR Gross Trade 3rd Party Allowance | C17: -42841.18 | D17: -40127.62 | E17: -2713.56 | F17: 6.8- | G17: =VLOOKUP(B17,'Profit & Loss'!$B$3:$C$390,2,0) -> #N/A
A18: 10202 | C18: -42841.18 | D18: -40127.62 | E18: -2713.56 | F18: 6.8- | G18: =VLOOKUP(B18,'Profit & Loss'!$B$3:$C$390,2,0) -> #N/A
A19: 102 | C19: 15121550 | D19: 15398589 | E19: -277039.3 | F19: 1.8- | G19: =VLOOKUP(B19,'Profit & Loss'!$B$3:$C$390,2,0) -> #N/A
A20: 10301 | B20: 1211101000 AR Claim Warranty Pending 3rd Party | C20: 0.01 | D20: 0.01 | E20: 0 | F20: 0.0 | G20: =VLOOKUP(B20,'Profit & Loss'!$B$3:$C$390,2,0) -> #N/A
A21: 10301 | B21: 1211101001 AR Claim Warranty Pend Claim 3rd Party New Acct | C21: 507.48 | D21: 0 | E21: 507.48 | G21: =VLOOKUP(B21,'Profit & Loss'!$B$3:$C$390,2,0) -> #N/A
A22: 10301 | B22: 1211201311 AR Claim TWLBR | C22: 51850.32 | D22: 42291.62 | E22: 9558.7 | F22: 22.6 | G22: =VLOOKUP(B22,'Profit & Loss'!$B$3:$C$390,2,0) -> #N/A
A23: 10301 | B23: 1211301000 AR Claim Warranty Claim 3rd Party | C23: 0.01 | D23: 0.01 | E23: 0 | F23: 0.0 | G23: =VLOOKUP(B23,'Profit & Loss'!$B$3:$C$390,2,0) -> #N/A
A24: 10301 | B24: 1211301001 AR Claim Warranty Claim 3rd Party New | C24: 118453.57 | D24: 27128.57 | E24: 91325 | F24: 336.6 | G24: =VLOOKUP(B24,'Profit & Loss'!$B$3:$C$390,2,0) -> #N/A
A25: 10301 | B25: 1211401001 AR Claim 3rd Party Goodwill (New Acct) | C25: 22605.02 | D25: 46253.61 | E25: -23648.59 | F25: 51.1- | G25: =VLOOKUP(B25,'Profit & Loss'!$B$3:$C$390,2,0) -> #N/A
A26: 10301 | B26: 1211401310 AR Claim Warranty Claim-Goodwill 3rd Party OEM | C26: 19.35 | D26: 19.35 | E26: 0 | F26: 0.0 | G26: =VLOOKUP(B26,'Profit & Loss'!$B$3:$C$390,2,0) -> #N/A
A27: 10301 | C27: 193435.76 | D27: 115693.17 | E27: 77742.59 | F27: 67.2 | G27: =VLOOKUP(B27,'Profit & Loss'!$B$3:$C$390,2,0) -> #N/A
A28: 10302 | B28: 1212001010 AR Claim 3rd Party CAT Parts Core | C28: 103211.52 | D28: -7566.42 | E28: 110777.94 | F28: 1,464.1 | G28: =VLOOKUP(B28,'Profit & Loss'!$B$3:$C$390,2,0) -> #N/A
A29: 10302 | C29: 103211.52 | D29: -7566.42 | E29: 110777.94 | F29: 1,464.1 | G29: =VLOOKUP(B29,'Profit & Loss'!$B$3:$C$390,2,0) -> #N/A
A30: 10306 | B30: 1110101230 AR Gross Trade 3rd Party Art23 | C30: 49147.55 | D30: 67008.31 | E30: -17860.76 | F30: 26.7- | G30: =VLOOKUP(B30,'Profit & Loss'!$B$3:$C$390,2,0) -> #N/A
A31: 10306 | B31: 1110101239 AR Gross Trade 3rd Party Art23 FxV | C31: -107.47 | D31: 14.94 | E31: -122.41 | F31: 819.3- | G31: =VLOOKUP(B31,'Profit & Loss'!$B$3:$C$390,2,0) -> #N/A
A32: 10306 | B32: 1110102230 AR Gross Trade Rel Party Art23 | C32: 0 | D32: 277.08 | E32: -277.08 | F32: 100.0- | G32: =VLOOKUP(B32,'Profit & Loss'!$B$3:$C$390,2,0) -> #N/A
A33: 10306 | B33: 1110102239 AR Gross Trade Rel Party Art23 FxV | C33: 0 | D33: 1.19 | E33: -1.19 | F33: 100.0- | G33: =VLOOKUP(B33,'Profit & Loss'!$B$3:$C$390,2,0) -> #N/A
A34: 10306 | B34: 1110181000 AR Gross Others Project System Over Under | C34: 2597.52 | D34: 2597.52 | E34: 0 | F34: 0.0 | G34: =VLOOKUP(B34,'Profit & Loss'!$B$3:$C$390,2,0) -> #N/A
A35: 10306 | B35: 1110202000 AR Gross Non Trade Rel Party | C35: 7843.4 | D35: 0 | E35: 7843.4 | G35: =VLOOKUP(B35,'Profit & Loss'!$B$3:$C$390,2,0) -> #N/A
A36: 10306 | B36: 1110202009 AR Gross Non Trade Rel Party FxV | C36: -14.27 | D36: 0 | E36: -14.27 | G36: =VLOOKUP(B36,'Profit & Loss'!$B$3:$C$390,2,0) -> #N/A
A37: 10306 | B37: 1216001020 AR Claim 3rd Party CAT PSDN | C37: -7666.86 | D37: 348.54 | E37: -8015.4 | F37: 2,299.7- | G37: =VLOOKUP(B37,'Profit & Loss'!$B$3:$C$390,2,0) -> #N/A
A38: 10306 | B38: 1219301000 AR Claim Others 3rd Party | C38: 2694.7 | D38: 2821.42 | E38: -126.72 | F38: 4.5- | G38: =VLOOKUP(B38,'Profit & Loss'!$B$3:$C$390,2,0) -> #N/A
A39: 10306 | B39: 1219301009 AR Claim Others 3rd Party FxV | C39: 0 | D39: -0.35 | E39: 0.35 | F39: 100.0 | G39: =VLOOKUP(B39,'Profit & Loss'!$B$3:$C$390,2,0) -> #N/A
A40: 10306 | B40: 1219302070 AR Claim Others Rel Party CKB | C40: 40.97 | D40: 39.9 | E40: 1.07 | F40: 2.7 | G40: =VLOOKUP(B40,'Profit & Loss'!$B$3:$C$390,2,0) -> #N/A
...

Sheet MAY 22
A1: Financial Statement Item | B1: Text for B/S P&L item | C1: Total of reporting period | D1: Total of the comparison period | E1: Absolute difference | F1: A
A2: 1000000 | B2: A S S E T S | C2: 0 | D2: 0 | E2: 0 | F2: =VLOOKUP(B2,'Profit & Loss'!$B$2:$C$390,2,0) -> #N/A
A3: 1000000 | B3: = = = = = = | C3: 0 | D3: 0 | E3: 0 | F3: =VLOOKUP(B3,'Profit & Loss'!$B$2:$C$390,2,0) -> #N/A
A4: 10101 | B4: 1011100380 PettyCash IDR SANGATTA | C4: 329.08 | D4: 329.08 | E4: 0 | F4: =VLOOKUP(B4,'Profit & Loss'!$B$2:$C$390,2,0) -> #N/A
A5: 10101 | B5: 1016109751 Bank IDR Mandiri 1480004169325 MB-SANGATA_COL | C5: 610.44 | D5: 610.44 | E5: 0 | F5: =VLOOKUP(B5,'Profit & Loss'!$B$2:$C$390,2,0) -> #N/A
A6: 10101 | B6: 1016109761 Bank IDR Mandiri 1480004169309 MB-SANGATA_OPR | C6: 27965.02 | D6: 23494.19 | E6: 4470.83 | F6: =VLOOKUP(B6,'Profit & Loss'!$B$2:$C$390,2,0) -> #N/A
A7: 10101 | B7: 1016109769 Bank IDR Mandiri 1480004169309 FxV-SANGATA_OPR | C7: -23414.15 | D7: -23412.73 | E7: -1.42 | F7: =VLOOKUP(B7,'Profit & Loss'!$B$2:$C$390,2,0) -> #N/A
A8: 10101 | B8: 1016162071 Bank IDR Mandiri 148-001-687266-8 MB SGT | C8: 68.61 | D8: 68.6 | E8: 0.01 | F8: =VLOOKUP(B8,'Profit & Loss'!$B$2:$C$390,2,0) -> #N/A
A9: 10101 | B9: 1016162079 Bank IDR Mandiri 148-001-687266-8 FxV SGT | C9: 1.87 | D9: 2.49 | E9: -0.62 | F9: =VLOOKUP(B9,'Profit & Loss'!$B$2:$C$390,2,0) -> #N/A
A10: 10101 | C10: 5560.87 | D10: 1092.07 | E10: 4468.8 | F10: =VLOOKUP(B10,'Profit & Loss'!$B$2:$C$390,2,0) -> #N/A
A11: 101 | C11: 5560.87 | D11: 1092.07 | E11: 4468.8 | F11: =VLOOKUP(B11,'Profit & Loss'!$B$2:$C$390,2,0) -> #N/A
A12: 10201 | B12: 1110101000 AR Gross Trade 3rd Party | C12: 15592930 | D12: 13702348 | E12: 1890582.1 | F12: =VLOOKUP(B12,'Profit & Loss'!$B$2:$C$390,2,0) -> #N/A
A13: 10201 | B13: 1110101009 AR Gross Trade 3rd Party FxV | C13: -42604.13 | D13: -35312.69 | E13: -7291.44 | F13: =VLOOKUP(B13,'Profit & Loss'!$B$2:$C$390,2,0) -> #N/A
